[2017-10-21 06:53:24,011 - rq.worker - DEBUG] - Registering birth of worker e8e68f7901e9.225
Traceback (most recent call last):
  File "/usr/local/lib/python3.4/dist-packages/redis-2.10.6-py3.4.egg/redis/connection.py", line 484, in connect
  File "/usr/local/lib/python3.4/dist-packages/redis-2.10.6-py3.4.egg/redis/connection.py", line 511, in _connect
  File "/usr/lib/python3.4/socket.py", line 530, in getaddrinfo
    for res in _socket.getaddrinfo(host, port, family, type, proto, flags):
socket.gaierror: [Errno -2] Name or service not known

During handling of the above exception, another exception occurred:

Traceback (most recent call last):
  File "/usr/local/lib/python3.4/dist-packages/redis-2.10.6-py3.4.egg/redis/client.py", line 667, in execute_command
  File "/usr/local/lib/python3.4/dist-packages/redis-2.10.6-py3.4.egg/redis/connection.py", line 610, in send_command
  File "/usr/local/lib/python3.4/dist-packages/redis-2.10.6-py3.4.egg/redis/connection.py", line 585, in send_packed_command
  File "/usr/local/lib/python3.4/dist-packages/redis-2.10.6-py3.4.egg/redis/connection.py", line 489, in connect
redis.exceptions.ConnectionError: Error -2 connecting to redis:6379. Name or service not known.

During handling of the above exception, another exception occurred:

Traceback (most recent call last):
  File "/usr/local/lib/python3.4/dist-packages/redis-2.10.6-py3.4.egg/redis/connection.py", line 484, in connect
  File "/usr/local/lib/python3.4/dist-packages/redis-2.10.6-py3.4.egg/redis/connection.py", line 511, in _connect
  File "/usr/lib/python3.4/socket.py", line 530, in getaddrinfo
    for res in _socket.getaddrinfo(host, port, family, type, proto, flags):
socket.gaierror: [Errno -2] Name or service not known

During handling of the above exception, another exception occurred:

Traceback (most recent call last):
  File "/usr/local/bin/arthurw", line 4, in <module>
    __import__('pkg_resources').run_script('arthur==0.1.0.dev1', 'arthurw')
  File "/usr/lib/python3/dist-packages/pkg_resources.py", line 534, in run_script
    self.require(requires)[0].run_script(script_name, ns)
  File "/usr/lib/python3/dist-packages/pkg_resources.py", line 1438, in run_script
    execfile(script_filename, namespace, namespace)
  File "/usr/lib/python3/dist-packages/pkg_resources.py", line 59, in execfile
    exec(compile(open(fn).read(), fn, 'exec'), globs, locs)
  File "/usr/local/lib/python3.4/dist-packages/arthur-0.1.0.dev1-py3.4.egg/EGG-INFO/scripts/arthurw", line 143, in <module>
    main()
  File "/usr/local/lib/python3.4/dist-packages/arthur-0.1.0.dev1-py3.4.egg/EGG-INFO/scripts/arthurw", line 75, in main
    w.work(burst=burst)
  File "/usr/local/lib/python3.4/dist-packages/rq-0.8.2-py3.4.egg/rq/worker.py", line 449, in work
    self.register_birth()
  File "/usr/local/lib/python3.4/dist-packages/rq-0.8.2-py3.4.egg/rq/worker.py", line 259, in register_birth
    if self.connection.exists(self.key) and \
  File "/usr/local/lib/python3.4/dist-packages/redis-2.10.6-py3.4.egg/redis/client.py", line 951, in exists
  File "/usr/local/lib/python3.4/dist-packages/redis-2.10.6-py3.4.egg/redis/client.py", line 673, in execute_command
  File "/usr/local/lib/python3.4/dist-packages/redis-2.10.6-py3.4.egg/redis/connection.py", line 610, in send_command
  File "/usr/local/lib/python3.4/dist-packages/redis-2.10.6-py3.4.egg/redis/connection.py", line 585, in send_packed_command
  File "/usr/local/lib/python3.4/dist-packages/redis-2.10.6-py3.4.egg/redis/connection.py", line 489, in connect
redis.exceptions.ConnectionError: Error -2 connecting to redis:6379. Name or service not known.
